Traceback (most recent call last):
  File "C:\Users\lenna\miniconda3\envs\jupyterbook\lib\site-packages\jupyter_cache\executors\utils.py", line 58, in single_nb_execution
    executenb(
  File "C:\Users\lenna\miniconda3\envs\jupyterbook\lib\site-packages\nbclient\client.py", line 1314, in execute
    return NotebookClient(nb=nb, resources=resources, km=km, **kwargs).execute()
  File "C:\Users\lenna\miniconda3\envs\jupyterbook\lib\site-packages\jupyter_core\utils\__init__.py", line 165, in wrapped
    return loop.run_until_complete(inner)
  File "C:\Users\lenna\miniconda3\envs\jupyterbook\lib\asyncio\base_events.py", line 649, in run_until_complete
    return future.result()
  File "C:\Users\lenna\miniconda3\envs\jupyterbook\lib\site-packages\nbclient\client.py", line 709, in async_execute
    await self.async_execute_cell(
  File "C:\Users\lenna\miniconda3\envs\jupyterbook\lib\site-packages\nbclient\client.py", line 1062, in async_execute_cell
    await self._check_raise_for_error(cell, cell_index, exec_reply)
  File "C:\Users\lenna\miniconda3\envs\jupyterbook\lib\site-packages\nbclient\client.py", line 918, in _check_raise_for_error
    raise CellExecutionError.from_cell_and_msg(cell, exec_reply_content)
nbclient.exceptions.CellExecutionError: An error occurred while executing the following cell:
------------------
from matplotlib import scale
import pandas as pd
import plotly.express as px
import plotly.graph_objects as go

df = pd.read_csv('A_AccidentsData.csv')
groottes = [(0, 5), (5, 50), (50, 500), (500, 5000), (5000, 500000)]
colors = ["Black", "Yellow", "Red", "Green", "Blue"]

scale = 0.03

fig = go.Figure()

for i in range(len(groottes)):
    lim = groottes[i]
    df_sub = df[(df['ongelukken'] >= lim[0]) & (df['ongelukken'] < lim[1])]
    fig.add_trace(go.Scattergeo(
        locationmode='USA-states',
        lon=df_sub['lng'],
        lat=df_sub['lat'],
        text=df_sub['City'] + ': ' + df_sub['ongelukken'].astype(str) + ' ongelukken',
        mode='markers',
        marker=dict(
            size=df_sub['ongelukken'] * scale,
            color=colors[i],
            line_color='rgb(40,40,40)',
            line_width=0.5,
            sizemode='area'
        ),
        name=f'{lim[0]} - {lim[1]} ongelukken'
    ))

fig.update_layout(
    title_text='Aantal ongelukken per stad in de VS',
    showlegend=True,
    geo=dict(
        scope='usa',
        landcolor='rgb(217, 217, 217)',
    )
)

fig.show()
------------------


[1;31m---------------------------------------------------------------------------[0m
[1;31mModuleNotFoundError[0m                       Traceback (most recent call last)
Cell [1;32mIn[1], line 1[0m
[1;32m----> 1[0m [38;5;28;01mfrom[39;00m [38;5;21;01mmatplotlib[39;00m [38;5;28;01mimport[39;00m scale
[0;32m      2[0m [38;5;28;01mimport[39;00m [38;5;21;01mpandas[39;00m [38;5;28;01mas[39;00m [38;5;21;01mpd[39;00m
[0;32m      3[0m [38;5;28;01mimport[39;00m [38;5;21;01mplotly[39;00m[38;5;21;01m.[39;00m[38;5;21;01mexpress[39;00m [38;5;28;01mas[39;00m [38;5;21;01mpx[39;00m

[1;31mModuleNotFoundError[0m: No module named 'matplotlib'

