Traceback (most recent call last):
  File "C:\Users\lenna\miniconda3\envs\jupyterbook\lib\site-packages\jupyter_cache\executors\utils.py", line 58, in single_nb_execution
    executenb(
  File "C:\Users\lenna\miniconda3\envs\jupyterbook\lib\site-packages\nbclient\client.py", line 1314, in execute
    return NotebookClient(nb=nb, resources=resources, km=km, **kwargs).execute()
  File "C:\Users\lenna\miniconda3\envs\jupyterbook\lib\site-packages\jupyter_core\utils\__init__.py", line 165, in wrapped
    return loop.run_until_complete(inner)
  File "C:\Users\lenna\miniconda3\envs\jupyterbook\lib\asyncio\base_events.py", line 649, in run_until_complete
    return future.result()
  File "C:\Users\lenna\miniconda3\envs\jupyterbook\lib\site-packages\nbclient\client.py", line 709, in async_execute
    await self.async_execute_cell(
  File "C:\Users\lenna\miniconda3\envs\jupyterbook\lib\site-packages\nbclient\client.py", line 1062, in async_execute_cell
    await self._check_raise_for_error(cell, cell_index, exec_reply)
  File "C:\Users\lenna\miniconda3\envs\jupyterbook\lib\site-packages\nbclient\client.py", line 918, in _check_raise_for_error
    raise CellExecutionError.from_cell_and_msg(cell, exec_reply_content)
nbclient.exceptions.CellExecutionError: An error occurred while executing the following cell:
------------------
from matplotlib import scale
import pandas as pd
import plotly.express as px
import plotly.graph_objects as go

df = pd.read_csv('W_WeatherBubbleData.csv')

grootte = [(0,0.30),(0.30,0.35),(0.35,0.40),(0.40,0.45),(0.45,0.50),(0.50,1)]
color_scale = px.colors.diverging.Tealrose

def assign_size(score):
    for i, (min_range, max_range) in enumerate(grootte):
        if min_range <= score < max_range:
            return (i + 1) * 5
    return 5 

hover_text = []
for index, row in df.iterrows():
    hover_text.append(f"City: {row['city']}<br>Score: {row['score']}")

fig = go.Figure()

fig.add_trace(go.Scattergeo(
    locationmode='USA-states',
    lon=df['lng'],
    lat=df['lat'],
    mode='markers',
    marker=dict(
        size=[assign_size(score) for score in df['score']],
        color=df['score'],
        colorscale=color_scale,
        colorbar=dict(title='Weather Score'),
        line_color='rgb(40, 40, 40)',
        line_width=0.5,
        sizemode='diameter',
        opacity=0.8
    ),
    text=hover_text,
    hoverinfo='text',
))

fig.update_layout(
    title='Weather score per grote stad in Amerika',
    geo=dict(
        scope='usa',
        landcolor='rgb(217, 217, 217)',
    )
)

fig.show()
------------------


[1;31m---------------------------------------------------------------------------[0m
[1;31mModuleNotFoundError[0m                       Traceback (most recent call last)
Cell [1;32mIn[1], line 1[0m
[1;32m----> 1[0m [38;5;28;01mfrom[39;00m [38;5;21;01mmatplotlib[39;00m [38;5;28;01mimport[39;00m scale
[0;32m      2[0m [38;5;28;01mimport[39;00m [38;5;21;01mpandas[39;00m [38;5;28;01mas[39;00m [38;5;21;01mpd[39;00m
[0;32m      3[0m [38;5;28;01mimport[39;00m [38;5;21;01mplotly[39;00m[38;5;21;01m.[39;00m[38;5;21;01mexpress[39;00m [38;5;28;01mas[39;00m [38;5;21;01mpx[39;00m

[1;31mModuleNotFoundError[0m: No module named 'matplotlib'

