Traceback (most recent call last):
  File "C:\Users\lenna\miniconda3\envs\jupyterbook\lib\site-packages\jupyter_cache\executors\utils.py", line 58, in single_nb_execution
    executenb(
  File "C:\Users\lenna\miniconda3\envs\jupyterbook\lib\site-packages\nbclient\client.py", line 1314, in execute
    return NotebookClient(nb=nb, resources=resources, km=km, **kwargs).execute()
  File "C:\Users\lenna\miniconda3\envs\jupyterbook\lib\site-packages\jupyter_core\utils\__init__.py", line 165, in wrapped
    return loop.run_until_complete(inner)
  File "C:\Users\lenna\miniconda3\envs\jupyterbook\lib\asyncio\base_events.py", line 649, in run_until_complete
    return future.result()
  File "C:\Users\lenna\miniconda3\envs\jupyterbook\lib\site-packages\nbclient\client.py", line 709, in async_execute
    await self.async_execute_cell(
  File "C:\Users\lenna\miniconda3\envs\jupyterbook\lib\site-packages\nbclient\client.py", line 1062, in async_execute_cell
    await self._check_raise_for_error(cell, cell_index, exec_reply)
  File "C:\Users\lenna\miniconda3\envs\jupyterbook\lib\site-packages\nbclient\client.py", line 918, in _check_raise_for_error
    raise CellExecutionError.from_cell_and_msg(cell, exec_reply_content)
nbclient.exceptions.CellExecutionError: An error occurred while executing the following cell:
------------------
import pandas as pd
import plotly.express as px
import ipywidgets as widgets
from IPython.display import display, clear_output

data = pd.read_csv('F_PlotData.csv')
data['Date'] = pd.to_datetime(data['Date'])

def update_figure(selected_date):
    filtered_data = data[data['Date'].dt.to_period('M') == selected_date]
    
    fig = px.scatter(filtered_data, 
                     x='Average_Severity', 
                     y='Weather_Score', 
                     color='Region', 
                     trendline='ols',  # Voeg een regressielijn toe
                     trendline_color_override='black',  # Kleur van de regressielijn
                     hover_data={'Region': True, 'Date': True},
                     facet_col='Region',
                     facet_col_wrap=3,
                     height=600,
                     width=1200,
                     labels={'Average_Severity': 'Average Severity', 'Weather_Score': 'Weather Score'}
                     )
    
    fig.update_layout(title="The impact of weather on the severity of traffic accidents, in the regions of the US, during a specific timeframe",
                      showlegend=False)
    fig.update_xaxes(range=[1.8, 4.2],  # Bereik van de x-as
                     dtick=1)       # Stapgrootte van de x-as
    fig.update_yaxes(range=[0.2, 1],  # Bereik van de x-as
                     dtick=1)       # Stapgrootte van de x-as
    
    clear_output(wait=True)
    display(date_dropdown)
    fig.show()

# Dropdown menu voor datumselectie
dates = ['2016-01', '2016-04', '2016-07', '2016-10', '2017-01', '2017-04', '2017-07', '2017-10']
date_dropdown = widgets.Dropdown(
    options=dates,
    value='2017-01',
    description='Date:'
)
display(date_dropdown)

def on_date_change(change):
    update_figure(change.new)

date_dropdown.observe(on_date_change, names='value')

update_figure('2017-01')

------------------


[1;31m---------------------------------------------------------------------------[0m
[1;31mModuleNotFoundError[0m                       Traceback (most recent call last)
Cell [1;32mIn[1], line 1[0m
[1;32m----> 1[0m [38;5;28;01mimport[39;00m [38;5;21;01mpandas[39;00m [38;5;28;01mas[39;00m [38;5;21;01mpd[39;00m
[0;32m      2[0m [38;5;28;01mimport[39;00m [38;5;21;01mplotly[39;00m[38;5;21;01m.[39;00m[38;5;21;01mexpress[39;00m [38;5;28;01mas[39;00m [38;5;21;01mpx[39;00m
[0;32m      3[0m [38;5;28;01mimport[39;00m [38;5;21;01mipywidgets[39;00m [38;5;28;01mas[39;00m [38;5;21;01mwidgets[39;00m

[1;31mModuleNotFoundError[0m: No module named 'pandas'

