Traceback (most recent call last):
  File "C:\Users\lenna\miniconda3\envs\jupyterbook\lib\site-packages\jupyter_cache\executors\utils.py", line 58, in single_nb_execution
    executenb(
  File "C:\Users\lenna\miniconda3\envs\jupyterbook\lib\site-packages\nbclient\client.py", line 1314, in execute
    return NotebookClient(nb=nb, resources=resources, km=km, **kwargs).execute()
  File "C:\Users\lenna\miniconda3\envs\jupyterbook\lib\site-packages\jupyter_core\utils\__init__.py", line 165, in wrapped
    return loop.run_until_complete(inner)
  File "C:\Users\lenna\miniconda3\envs\jupyterbook\lib\asyncio\base_events.py", line 649, in run_until_complete
    return future.result()
  File "C:\Users\lenna\miniconda3\envs\jupyterbook\lib\site-packages\nbclient\client.py", line 709, in async_execute
    await self.async_execute_cell(
  File "C:\Users\lenna\miniconda3\envs\jupyterbook\lib\site-packages\nbclient\client.py", line 1062, in async_execute_cell
    await self._check_raise_for_error(cell, cell_index, exec_reply)
  File "C:\Users\lenna\miniconda3\envs\jupyterbook\lib\site-packages\nbclient\client.py", line 918, in _check_raise_for_error
    raise CellExecutionError.from_cell_and_msg(cell, exec_reply_content)
nbclient.exceptions.CellExecutionError: An error occurred while executing the following cell:
------------------
import plotly.express as px
import pandas as pd
accidents = pd.read_csv('../resources/us_accidents.csv')

accidents['Start_Time'] = pd.to_datetime(accidents['Start_Time'])
date_counts = accidents['Start_Time'].dt.date.value_counts().sort_index()

# Create a bar chart with Plotly
fig = px.bar(
    x=date_counts.index,
    y=date_counts.values,
    labels={'x': 'Date', 'y': 'Number of Accidents'},
    title='Number of Accidents per Day',
    color_discrete_sequence= ['red']
)

# Update the layout to improve appearance
fig.update_layout(
    xaxis_title='Date',
    yaxis_title='Number of Accidents',
    xaxis_tickangle=-90
)

# Show the plot
fig.show()
------------------


[1;31m---------------------------------------------------------------------------[0m
[1;31mImportError[0m                               Traceback (most recent call last)
Cell [1;32mIn[1], line 1[0m
[1;32m----> 1[0m [38;5;28;01mimport[39;00m [38;5;21;01mplotly[39;00m[38;5;21;01m.[39;00m[38;5;21;01mexpress[39;00m [38;5;28;01mas[39;00m [38;5;21;01mpx[39;00m
[0;32m      2[0m [38;5;28;01mimport[39;00m [38;5;21;01mpandas[39;00m [38;5;28;01mas[39;00m [38;5;21;01mpd[39;00m
[0;32m      3[0m accidents [38;5;241m=[39m pd[38;5;241m.[39mread_csv([38;5;124m'[39m[38;5;124m../resources/us_accidents.csv[39m[38;5;124m'[39m)

File [1;32m~\miniconda3\envs\jupyterbook\lib\site-packages\plotly\express\__init__.py:9[0m
[0;32m      7[0m pd [38;5;241m=[39m optional_imports[38;5;241m.[39mget_module([38;5;124m"[39m[38;5;124mpandas[39m[38;5;124m"[39m)
[0;32m      8[0m [38;5;28;01mif[39;00m pd [38;5;129;01mis[39;00m [38;5;28;01mNone[39;00m:
[1;32m----> 9[0m     [38;5;28;01mraise[39;00m [38;5;167;01mImportError[39;00m(
[0;32m     10[0m [38;5;250m        [39m[38;5;124;03m"""\[39;00m
[0;32m     11[0m [38;5;124;03mPlotly express requires pandas to be installed."""[39;00m
[0;32m     12[0m     )
[0;32m     14[0m [38;5;28;01mfrom[39;00m [38;5;21;01m.[39;00m[38;5;21;01m_imshow[39;00m [38;5;28;01mimport[39;00m imshow
[0;32m     15[0m [38;5;28;01mfrom[39;00m [38;5;21;01m.[39;00m[38;5;21;01m_chart_types[39;00m [38;5;28;01mimport[39;00m (  [38;5;66;03m# noqa: F401[39;00m
[0;32m     16[0m     scatter,
[0;32m     17[0m     scatter_3d,
[1;32m   (...)[0m
[0;32m     50[0m     density_mapbox,
[0;32m     51[0m )

[1;31mImportError[0m: Plotly express requires pandas to be installed.

